Workbook

Sheet Capital Est
A1: DATE | B1: K_Australia | C1: K_Canada | D1: K_Germany | E1: K_Estonia | F1: K_France | G1: K_GB | H1: K_Italy | I1: K_Japan | J1: K_Mexico | K1: K_Turkey | L1: K_US
A2: 18264 | B2: =IF(INV!B3="","",0)
A3: 18629 | B3: =IF(INV!B4="","",0)
A4: 18994 | B4: =IF(INV!B5="","",0)
A5: 19360 | B5: =IF(INV!B6="","",0)
A6: 19725 | B6: =IF(INV!B7="","",0) | D6: =IF(INV!D7="","",3*GDP!D8) | E6: =IF(INV!E7="","",3*GDP!E8) | F6: =IF(INV!F7="","",3*GDP!F8) | G6: =IF(INV!G7="","",3*GDP!G8) | H6: =IF(INV!H7="","",3*GDP!H8) | I6: =IF(INV!I7="","",3*GDP!I8) | J6: =IF(INV!J7="","",3*GDP!J8) | K6: =IF(INV!K7="","",3*GDP!K8)
A7: 20090 | B7: =IF(INV!B8="","",0) | D7: =IF(INV!D8="","",3*GDP!D9) | E7: =IF(INV!E8="","",3*GDP!E9) | F7: =IF(INV!F8="","",3*GDP!F9) | G7: =IF(INV!G8="","",3*GDP!G9) | H7: =IF(INV!H8="","",3*GDP!H9) | I7: =IF(INV!I8="","",3*GDP!I9) | J7: =IF(INV!J8="","",3*GDP!J9) | K7: =IF(INV!K8="","",3*GDP!K9)
A8: 20455 | B8: =IF(INV!B9="","",0) | D8: =IF(INV!D9="","",3*GDP!D10) | E8: =IF(INV!E9="","",3*GDP!E10) | F8: =IF(INV!F9="","",3*GDP!F10) | G8: =IF(INV!G9="","",3*GDP!G10) | H8: =IF(INV!H9="","",3*GDP!H10) | I8: =IF(INV!I9="","",3*GDP!I10) | J8: =IF(INV!J9="","",3*GDP!J10) | K8: =IF(INV!K9="","",3*GDP!K10)
A9: 20821 | B9: =IF(INV!B10="","",0) | D9: =IF(INV!D10="","",3*GDP!D11) | E9: =IF(INV!E10="","",3*GDP!E11) | F9: =IF(INV!F10="","",3*GDP!F11) | G9: =IF(INV!G10="","",3*GDP!G11) | H9: =IF(INV!H10="","",3*GDP!H11) | I9: =IF(INV!I10="","",3*GDP!I11) | J9: =IF(INV!J10="","",3*GDP!J11) | K9: =IF(INV!K10="","",3*GDP!K11)
A10: 21186 | B10: =IF(INV!B11="","",3*GDP!B11) | C10: =IF(INV!C11="","",3*GDP!C11) | D10: =IF(INV!D11="","",3*GDP!D11) | E10: =IF(INV!E11="","",3*GDP!E11) | F10: =IF(INV!F11="","",3*GDP!F11) -> 1225024.3 | G10: =IF(INV!G11="","",3*GDP!G11) | H10: =IF(INV!H11="","",3*GDP!H11) | I10: =IF(INV!I11="","",3*GDP!I11) | ... K10: =IF(INV!K11="","",3*GDP!K11)
A11: 21551 | B11: =IF(INV!B12="","",3*GDP!B12) -> 921084 | C11: =IF(INV!C12="","",3*GDP!C12) | D11: =IF(INV!D12="","",3*GDP!D12) | E11: =IF(INV!E12="","",3*GDP!E12) | F11: =(0.96)*F10+INV!F11 -> 1265701.8 | G11: =IF(INV!G12="","",3*GDP!G12) | H11: =IF(INV!H12="","",3*GDP!H12) | I11: =IF(INV!I12="","",3*GDP!I12) | J11: =IF(INV!J12="","",3*GDP!J12) | K11: =IF(INV!K12="","",3*GDP!K12)
A12: 21916 | B12: =(0.96)*B11+INV!B12 -> 931125.64 | C12: =IF(INV!C13="","",3*GDP!C13) -> 1130022.9 | D12: =IF(INV!D13="","",3*GDP!D13) | E12: =IF(INV!E13="","",3*GDP!E13) | F12: =(0.96)*F11+INV!F12 -> 1310726.3 | G12: =IF(INV!G13="","",3*GDP!G13) | H12: =IF(INV!H13="","",3*GDP!H13) | I12: =IF(INV!I13="","",3*GDP!I13) | J12: =IF(INV!J13="","",3*GDP!J13) | K12: =IF(INV!K13="","",3*GDP!K13)
A13: 22282 | B13: =(0.96)*B12+INV!B13 -> 943735.61 | C13: =(0.96)*C12+INV!C13 -> 1152221.1 | D13: =IF(INV!D14="","",3*GDP!D14) | E13: =IF(INV!E14="","",3*GDP!E14) | F13: =(0.96)*F12+INV!F13 -> 1365007.6 | G13: =IF(INV!G14="","",3*GDP!G14) | H13: =IF(INV!H14="","",3*GDP!H14) | I13: =IF(INV!I14="","",3*GDP!I14) | J13: =IF(INV!J14="","",3*GDP!J14) | K13: =IF(INV!K14="","",3*GDP!K14)
A14: 22647 | B14: =(0.96)*B13+INV!B14 -> 956364.19 | C14: =(0.96)*C13+INV!C14 -> 1176873 | D14: =IF(INV!D15="","",3*GDP!D15) | E14: =IF(INV!E15="","",3*GDP!E15) | F14: =(0.96)*F13+INV!F14 -> 1424419.3 | G14: =IF(INV!G15="","",3*GDP!G15) | H14: =IF(INV!H15="","",3*GDP!H15) | I14: =IF(INV!I15="","",3*GDP!I15) | J14: =IF(INV!J15="","",3*GDP!J15) | K14: =IF(INV!K15="","",3*GDP!K15)
A15: 23012 | B15: =(0.96)*B14+INV!B15 -> 973345.62 | C15: =(0.96)*C14+INV!C15 -> 1203165.9 | D15: =IF(INV!D16="","",3*GDP!D16) | E15: =IF(INV!E16="","",3*GDP!E16) | F15: =(0.96)*F14+INV!F15 -> 1490830 | G15: =IF(INV!G16="","",3*GDP!G16) | H15: =IF(INV!H16="","",3*GDP!H16) | I15: =IF(INV!I16="","",3*GDP!I16) | J15: =IF(INV!J16="","",3*GDP!J16) | K15: =IF(INV!K16="","",3*GDP!K16)
A16: 23377 | B16: =(0.96)*B15+INV!B16 -> 994241.8 | C16: =(0.96)*C15+INV!C16 -> 1238022.2 | D16: =IF(INV!D17="","",3*GDP!D17) | E16: =IF(INV!E17="","",3*GDP!E17) | F16: =(0.96)*F15+INV!F16 -> 1567325.3 | G16: =IF(INV!G17="","",3*GDP!G17) | H16: =IF(INV!H17="","",3*GDP!H17) | I16: =IF(INV!I17="","",3*GDP!I17) | J16: =IF(INV!J17="","",3*GDP!J17) | K16: =IF(INV!K17="","",3*GDP!K17)
A17: 23743 | B17: =(0.96)*B16+INV!B17 -> 1019389.1 | C17: =(0.96)*C16+INV!C17 -> 1280492.7 | D17: =IF(INV!D18="","",3*GDP!D18) | E17: =IF(INV!E18="","",3*GDP!E18) | F17: =(0.96)*F16+INV!F17 -> 1648493 | G17: =IF(INV!G18="","",3*GDP!G18) | H17: =IF(INV!H18="","",3*GDP!H18) | I17: =IF(INV!I18="","",3*GDP!I18) | J17: =IF(INV!J18="","",3*GDP!J18) | K17: =IF(INV!K18="","",3*GDP!K18)
A18: 24108 | B18: =(0.96)*B17+INV!B18 -> 1047144.6 | C18: =(0.96)*C17+INV!C18 -> 1331418.9 | D18: =IF(INV!D19="","",3*GDP!D19) | E18: =IF(INV!E19="","",3*GDP!E19) | F18: =(0.96)*F17+INV!F18 -> 1737224.8 | G18: =IF(INV!G19="","",3*GDP!G19) | H18: =IF(INV!H19="","",3*GDP!H19) | I18: =IF(INV!I19="","",3*GDP!I19) | J18: =IF(INV!J19="","",3*GDP!J19) | K18: =IF(INV!K19="","",3*GDP!K19)
A19: 24473 | B19: =(0.96)*B18+INV!B19 -> 1077987.8 | C19: =(0.96)*C18+INV!C19 -> 1380406.3 | D19: =IF(INV!D20="","",3*GDP!D20) | E19: =IF(INV!E20="","",3*GDP!E20) | F19: =(0.96)*F18+INV!F19 -> 1833799.9 | G19: =IF(INV!G20="","",3*GDP!G20) | H19: =IF(INV!H20="","",3*GDP!H20) | I19: =IF(INV!I20="","",3*GDP!I20) | J19: =IF(INV!J20="","",3*GDP!J20) | K19: =IF(INV!K20="","",3*GDP!K20)
A20: 24838 | B20: =(0.96)*B19+INV!B20 -> 1113345.3 | C20: =(0.96)*C19+INV!C20 -> 1428308.9 | D20: =IF(INV!D21="","",3*GDP!D21) | E20: =IF(INV!E21="","",3*GDP!E21) | F20: =(0.96)*F19+INV!F20 -> 1935709.3 | G20: =IF(INV!G21="","",3*GDP!G21) | H20: =IF(INV!H21="","",3*GDP!H21) | I20: =IF(INV!I21="","",3*GDP!I21) | J20: =IF(INV!J21="","",3*GDP!J21) | K20: =IF(INV!K21="","",3*GDP!K21)
A21: 25204 | B21: =(0.96)*B20+INV!B21 -> 1150832.5 | C21: =(0.96)*C20+INV!C21 -> 1479244.3 | D21: =IF(INV!D22="","",3*GDP!D22) | E21: =IF(INV!E22="","",3*GDP!E22) | F21: =(0.96)*F20+INV!F21 -> 2046882.2 | G21: =IF(INV!G22="","",3*GDP!G22) | H21: =IF(INV!H22="","",3*GDP!H22) | I21: =IF(INV!I22="","",3*GDP!I22) | J21: =IF(INV!J22="","",3*GDP!J22) | K21: =IF(INV!K22="","",3*GDP!K22)
A22: 25569 | B22: =(0.96)*B21+INV!B22 -> 1188887.2 | C22: =(0.96)*C21+INV!C22 -> 1528754.2 | D22: =IF(INV!D23="","",3*GDP!D23) | E22: =IF(INV!E23="","",3*GDP!E23) | F22: =(0.96)*F21+INV!F22 -> 2163852.6 | G22: =IF(INV!G23="","",3*GDP!G23) | H22: =IF(INV!H23="","",3*GDP!H23) | I22: =IF(INV!I23="","",3*GDP!I23) | J22: =IF(INV!J23="","",3*GDP!J23) | K22: =IF(INV!K23="","",3*GDP!K23)
A23: 25934 | B23: =(0.96)*B22+INV!B23 -> 1229541.7 | C23: =(0.96)*C22+INV!C23 -> 1584173.3 | D23: =IF(INV!D24="","",3*GDP!D24) | E23: =IF(INV!E24="","",3*GDP!E24) | F23: =(0.96)*F22+INV!F23 -> 2289492.2 | G23: =IF(INV!G24="","",3*GDP!G24) | H23: =IF(INV!H24="","",3*GDP!H24) | I23: =IF(INV!I24="","",3*GDP!I24) | J23: =IF(INV!J24="","",3*GDP!J24) | K23: =IF(INV!K24="","",3*GDP!K24) | L23: =GDP!L23*3 -> 16474336
A24: 26299 | B24: =(0.96)*B23+INV!B24 -> 1268823 | C24: =(0.96)*C23+INV!C24 -> 1642189.3 | D24: =IF(INV!D25="","",3*GDP!D25) | E24: =IF(INV!E25="","",3*GDP!E25) | F24: =(0.96)*F23+INV!F24 -> 2422351.2 | G24: =IF(INV!G25="","",3*GDP!G25) | H24: =IF(INV!H25="","",3*GDP!H25) | I24: =IF(INV!I25="","",3*GDP!I25) | J24: =IF(INV!J25="","",3*GDP!J25) | K24: =IF(INV!K25="","",3*GDP!K25) | L24: =(0.96)*L23+INV!L24 -> 16787310
A25: 26665 | B25: =(0.96)*B24+INV!B25 -> 1311957.1 | C25: =(0.96)*C24+INV!C25 -> 1707842.6 | D25: =IF(INV!D26="","",3*GDP!D26) | E25: =IF(INV!E26="","",3*GDP!E26) | F25: =(0.96)*F24+INV!F25 -> 2565131.5 | G25: =IF(INV!G26="","",3*GDP!G26) | H25: =IF(INV!H26="","",3*GDP!H26) | I25: =IF(INV!I26="","",3*GDP!I26) | J25: =IF(INV!J26="","",3*GDP!J26) | K25: =IF(INV!K26="","",3*GDP!K26) | L25: =(0.96)*L24+INV!L25 -> 17156549
A26: 27030 | B26: =(0.96)*B25+INV!B26 -> 1350635.8 | C26: =(0.96)*C25+INV!C26 -> 1777936.6 | D26: =IF(INV!D27="","",3*GDP!D27) | E26: =IF(INV!E27="","",3*GDP!E27) | F26: =(0.96)*F25+INV!F26 -> 2707639.1 | G26: =IF(INV!G27="","",3*GDP!G27) | H26: =IF(INV!H27="","",3*GDP!H27) | I26: =IF(INV!I27="","",3*GDP!I27) | J26: =IF(INV!J27="","",3*GDP!J27) | K26: =IF(INV!K27="","",3*GDP!K27) | L26: =(0.96)*L25+INV!L26 -> 17470396
A27: 27395 | B27: =(0.96)*B26+INV!B27 -> 1386266.4 | C27: =(0.96)*C26+INV!C27 -> 1851105 | D27: =IF(INV!D28="","",3*GDP!D28) | E27: =IF(INV!E28="","",3*GDP!E28) | F27: =(0.96)*F26+INV!F27 -> 2831956.1 | G27: =IF(INV!G28="","",3*GDP!G28) | H27: =IF(INV!H28="","",3*GDP!H28) | I27: =IF(INV!I28="","",3*GDP!I28) | J27: =IF(INV!J28="","",3*GDP!J28) | K27: =IF(INV!K28="","",3*GDP!K28) | L27: =(0.96)*L26+INV!L27 -> 17698681
A28: 27760 | B28: =(0.96)*B27+INV!B28 -> 1424468.7 | C28: =(0.96)*C27+INV!C28 -> 1930590.4 | D28: =IF(INV!D29="","",3*GDP!D29) | E28: =IF(INV!E29="","",3*GDP!E29) | F28: =(0.96)*F27+INV!F28 -> 2956598.5 | G28: =IF(INV!G29="","",3*GDP!G29) | H28: =IF(INV!H29="","",3*GDP!H29) | I28: =IF(INV!I29="","",3*GDP!I29) | J28: =IF(INV!J29="","",3*GDP!J29) | K28: =IF(INV!K29="","",3*GDP!K29) | L28: =(0.96)*L27+INV!L28 -> 17992301
A29: 28126 | B29: =(0.96)*B28+INV!B29 -> 1463761 | C29: =(0.96)*C28+INV!C29 -> 2010634.6 | D29: =IF(INV!D30="","",3*GDP!D30) | E29: =IF(INV!E30="","",3*GDP!E30) | F29: =(0.96)*F28+INV!F29 -> 3074609.3 | G29: =IF(INV!G30="","",3*GDP!G30) | H29: =IF(INV!H30="","",3*GDP!H30) | I29: =IF(INV!I30="","",3*GDP!I30) | J29: =IF(INV!J30="","",3*GDP!J30) | K29: =IF(INV!K30="","",3*GDP!K30) | L29: =(0.96)*L28+INV!L29 -> 18377626
A30: 28491 | B30: =(0.96)*B29+INV!B30 -> 1509038.5 | C30: =(0.96)*C29+INV!C30 -> 2090423.1 | D30: =IF(INV!D31="","",3*GDP!D31) | E30: =IF(INV!E31="","",3*GDP!E31) | F30: =(0.96)*F29+INV!F30 -> 3194262.5 | G30: =IF(INV!G31="","",3*GDP!G31) | H30: =IF(INV!H31="","",3*GDP!H31) | I30: =IF(INV!I31="","",3*GDP!I31) | J30: =IF(INV!J31="","",3*GDP!J31) | K30: =IF(INV!K31="","",3*GDP!K31) | L30: =(0.96)*L29+INV!L30 -> 18865258
A31: 28856 | B31: =(0.96)*B30+INV!B31 -> 1559033 | C31: =(0.96)*C30+INV!C31 -> 2177111.3 | D31: =IF(INV!D32="","",3*GDP!D32) | E31: =IF(INV!E32="","",3*GDP!E32) | F31: =(0.96)*F30+INV!F31 -> 3316030.3 | G31: =IF(INV!G32="","",3*GDP!G32) | H31: =IF(INV!H32="","",3*GDP!H32) | I31: =IF(INV!I32="","",3*GDP!I32) | J31: =IF(INV!J32="","",3*GDP!J32) | K31: =IF(INV!K32="","",3*GDP!K32) | L31: =(0.96)*L30+INV!L31 -> 19403067
A32: 29221 | B32: =(0.96)*B31+INV!B32 -> 1615660.7 | C32: =(0.96)*C31+INV!C32 -> 2269553.8 | D32: =IF(INV!D33="","",3*GDP!D33) | E32: =IF(INV!E33="","",3*GDP!E33) | F32: =(0.96)*F31+INV!F32 -> 3440149.2 | G32: =IF(INV!G33="","",3*GDP!G33) | H32: =IF(INV!H33="","",3*GDP!H33) | I32: =IF(INV!I33="","",3*GDP!I33) | J32: =IF(INV!J33="","",3*GDP!J33) | K32: =IF(INV!K33="","",3*GDP!K33) | L32: =(0.96)*L31+INV!L32 -> 19863887
A33: 29587 | B33: =(0.96)*B32+INV!B33 -> 1683274.2 | C33: =(0.96)*C32+INV!C33 -> 2374602.8 | D33: =IF(INV!D34="","",3*GDP!D34) | E33: =IF(INV!E34="","",3*GDP!E34) | F33: =(0.96)*F32+INV!F33 -> 3556485 | G33: =IF(INV!G34="","",3*GDP!G34) | H33: =IF(INV!H34="","",3*GDP!H34) | I33: =IF(INV!I34="","",3*GDP!I34) | J33: =IF(INV!J34="","",3*GDP!J34) | K33: =IF(INV!K34="","",3*GDP!K34) | L33: =(0.96)*L32+INV!L33 -> 20329873
A34: 29952 | B34: =(0.96)*B33+INV!B34 -> 1745930.3 | C34: =(0.96)*C33+INV!C34 -> 2454346.5 | D34: =IF(INV!D35="","",3*GDP!D35) | E34: =IF(INV!E35="","",3*GDP!E35) | F34: =(0.96)*F33+INV!F34 -> 3666010.3 | G34: =IF(INV!G35="","",3*GDP!G35) | H34: =IF(INV!H35="","",3*GDP!H35) | I34: =IF(INV!I35="","",3*GDP!I35) | J34: =IF(INV!J35="","",3*GDP!J35) | K34: =IF(INV!K35="","",3*GDP!K35) | L34: =(0.96)*L33+INV!L34 -> 20714625
A35: 30317 | B35: =(0.96)*B34+INV!B35 -> 1797635.1 | C35: =(0.96)*C34+INV!C35 -> 2529658.4 | D35: =IF(INV!D36="","",3*GDP!D36) | E35: =IF(INV!E36="","",3*GDP!E36) | F35: =(0.96)*F34+INV!F35 -> 3762653.4 | G35: =IF(INV!G36="","",3*GDP!G36) | H35: =IF(INV!H36="","",3*GDP!H36) | I35: =IF(INV!I36="","",3*GDP!I36) | J35: =IF(INV!J36="","",3*GDP!J36) | K35: =IF(INV!K36="","",3*GDP!K36) | L35: =(0.96)*L34+INV!L35 -> 21170950
... A42: 32874 | B42: =(0.96)*B41+INV!B42 -> 2344442.6 | C42: =(0.96)*C41+INV!C42 -> 3260167.3 | D42: =IF(INV!D43="","",3*GDP!D43) -> 6188308.8 | E42: =IF(INV!E43="","",3*GDP!E43) | F42: =(0.96)*F41+INV!F42 -> 4564244.1 | G42: =IF(INV!G43="","",3*GDP!G43) | H42: =IF(INV!H43="","",3*GDP!H43) | I42: =IF(INV!I43="","",3*GDP!I43) | J42: =IF(INV!J43="","",3*GDP!J43) | K42: =IF(INV!K43="","",3*GDP!K43) | L42: =(0.96)*L41+INV!L42 -> 26198098
A43: 33239 | B43: =(0.96)*B42+INV!B43 -> 2406714.9 | C43: =(0.96)*C42+INV!C43 -> 3361075.3 | D43: =(0.96)*D42+INV!D43 -> 6391081.1 | E43: =IF(INV!E44="","",3*GDP!E44) | F43: =(0.96)*F42+INV!F43 -> 4706011.9 | G43: =IF(INV!G44="","",3*GDP!G44) | H43: =IF(INV!H44="","",3*GDP!H44) | I43: =IF(INV!I44="","",3*GDP!I44) | J43: =IF(INV!J44="","",3*GDP!J44) | K43: =IF(INV!K44="","",3*GDP!K44) | L43: =(0.96)*L42+INV!L43 -> 26824627
A44: 33604 | B44: =(0.96)*B43+INV!B44 -> 2471565.3 | C44: =(0.96)*C43+INV!C44 -> 3451147.6 | D44: =(0.96)*D43+INV!D44 -> 6603754.6 | E44: =IF(INV!E45="","",3*GDP!E45) | F44: =(0.96)*F43+INV!F44 -> 4835318.5 | G44: =IF(INV!G45="","",3*GDP!G45) | H44: =IF(INV!H45="","",3*GDP!H45) | I44: =IF(INV!I45="","",3*GDP!I45) | J44: =IF(INV!J45="","",3*GDP!J45) -> 41691323 | K44: =IF(INV!K45="","",3*GDP!K45) | L44: =(0.96)*L43+INV!L44 -> 27494748
A45: 33970 | B45: =(0.96)*B44+INV!B45 -> 2542117.7 | C45: =(0.96)*C44+INV!C45 -> 3535009.5 | D45: =(0.96)*D44+INV!D45 -> 6787948.6 | E45: =IF(INV!E46="","",3*GDP!E46) | F45: =(0.96)*F44+INV!F45 -> 4941411.8 | G45: =IF(INV!G46="","",3*GDP!G46) | H45: =IF(INV!H46="","",3*GDP!H46) | I45: =IF(INV!I46="","",3*GDP!I46) -> 1339566888 | J45: =(0.96)*J44+INV!J45 -> 43144621 | K45: =IF(INV!K46="","",3*GDP!K46) | L45: =(0.96)*L44+INV!L45 -> 28226875
A46: 34335 | B46: =(0.96)*B45+INV!B46 -> 2633002 | C46: =(0.96)*C45+INV!C46 -> 3630387.8 | D46: =(0.96)*D45+INV!D46 -> 6980826.4 | E46: =IF(INV!E47="","",3*GDP!E47) -> 2162535.6 | F46: =(0.96)*F45+INV!F46 -> 5047404.9 | G46: =IF(INV!G47="","",3*GDP!G47) -> 4065069 | H46: =IF(INV!H47="","",3*GDP!H47) -> 4248354.5 | I46: =(0.96)*I45+INV!I46 -> 1.4270814e+09 | J46: =(0.96)*J45+INV!J46 -> 44950487 | K46: =IF(INV!K47="","",3*GDP!K47) | L46: =(0.96)*L45+INV!L46 -> 29041553
...

Sheet INV
A1: DATE | B1: NFIRXDCAUA | C1: NFIRXDCCAA | D1: NFIRXDCDEA | E1: NFIRXDCESA | F1: NFIRXDCFRA | G1: NFIRXDCGBA | H1: NFIRXDCITA | I1: NFIRXDCJPA | J1: NFIRXDCMXA | K1: NFIRXDCTRA | L1: NFIRXDCUSA
A2: 18264
A3: 18629
A4: 18994
A5: 19360
A6: 19725
A7: 20090
A8: 20455
A9: 20821
A10: 21186
A11: 21551 | F11: 89678.478 | L11: =NA() -> #N/A
A12: 21916 | B12: 46885 | F12: 95652.58 | L12: =NA() -> #N/A
A13: 22282 | B13: 49855 | C13: 67399.101 | F13: 106710.37 | L13: =NA() -> #N/A
A14: 22647 | B14: 50378 | C14: 70740.801 | F14: 114011.95 | L14: =NA() -> #N/A
A15: 23012 | B15: 55236 | C15: 73367.801 | F15: 123387.54 | L15: =NA() -> #N/A
A16: 23377 | B16: 59830 | C16: 82982.902 | F16: 136128.43 | L16: =NA() -> #N/A
A17: 23743 | B17: 64917 | C17: 91991.402 | F17: 143860.73 | L17: =NA() -> #N/A
A18: 24108 | B18: 68531 | C18: 102145.9 | F18: 154671.49 | L18: =NA() -> #N/A
A19: 24473 | B19: 72729 | C19: 102244.2 | F19: 166064.08 | L19: =NA() -> #N/A
A20: 24838 | B20: 78477 | C20: 103118.8 | F20: 175261.41 | L20: =NA() -> #N/A
A21: 25204 | B21: 82021 | C21: 108067.8 | F21: 188601.34 | L21: =NA() -> #N/A
A22: 25569 | B22: 84088 | C22: 108679.6 | F22: 198845.63 | L22: =NA() -> #N/A
A23: 25934 | B23: 88210 | C23: 116569.3 | F23: 212193.7 | L23: =NA() -> #N/A
A24: 26299 | B24: 88463 | C24: 121382.9 | F24: 224438.71 | L24: 971946.59
A25: 26665 | B25: 93887 | C25: 131340.9 | F25: 239674.38 | L25: 1040731.6
A26: 27030 | B26: 91157 | C26: 138407.7 | F26: 245112.79 | L26: 1000109
A27: 27395 | B27: 89656 | C27: 144285.9 | F27: 232622.56 | L27: 927100.69
A28: 27760 | B28: 93653 | C28: 153529.6 | F28: 237920.7 | L28: 1001567
A29: 28126 | B29: 96271 | C29: 157267.8 | F29: 236274.7 | L29: 1105017.6
A30: 28491 | B30: 103828 | C30: 160213.9 | F30: 242637.55 | L30: 1222736.9
A31: 28856 | B31: 110356 | C31: 170305.1 | F31: 249538.35 | L31: 1292419.6
A32: 29221 | B32: 118989 | C32: 179526.9 | F32: 256760.11 | L32: 1236942.6
A33: 29587 | B33: 132240 | C33: 195831.2 | F33: 253941.74 | L33: 1260541.3
A34: 29952 | B34: 129987 | C34: 174727.8 | F34: 251784.74 | L34: 1197946.8
A35: 30317 | B35: 121542 | C35: 173485.8 | F35: 243283.46 | L35: 1284909.8
... A42: 32874 | B42: 172458 | C42: 241514.7 | F42: 326009.38 | L42: 1746168.3
A43: 33239 | B43: 156050 | C43: 231314.7 | D43: 450304.62 | F43: 324337.59 | L43: 1674452.8
A44: 33604 | B44: 161119 | C44: 224515.3 | D44: 468316.8 | F44: 317547.09 | L44: 1743105.8
A45: 33970 | B45: 169415 | C45: 221907.8 | D45: 448344.11 | F45: 299506.07 | J45: 3120950.2 | L45: 1831917.4
A46: 34335 | B46: 192569 | C46: 236778.7 | D46: 464395.78 | F46: 303649.57 | I46: 141097200 | J46: 3531651.6 | L46: 1943752.3
...

Sheet GDP
A1: DATE | B1: NGDPRXDCAUA | C1: NGDPRXDCCAA | D1: NGDPRXDCDEA | E1: NGDPRXDCESA | F1: NGDPRXDCFRA | G1: NGDPRXDCGBA | H1: NGDPRXDCITA | I1: NGDPRXDCJPA | J1: NGDPRXDCMXA | K1: NGDPRXDCTRA | L1: NGDPRXDCUSA
A2: 18264 | F2: 277736.36 | L2: 2458531.8
A3: 18629 | F3: 293445.01 | L3: 2656320.1
A4: 18994 | F4: 302637.52 | L4: 2764803.1
A5: 19360 | F5: 312822.76 | L5: 2894411.9
A6: 19725 | F6: 330661.54 | L6: 2877707.8
A7: 20090 | F7: 348440.12 | L7: 3083025.8
A8: 20455 | F8: 366030.04 | L8: 3148765
A9: 20821 | F9: 386596.38 | L9: 3215065.3
A10: 21186 | F10: 397336.85 | L10: 3191216
A11: 21551 | F11: 408341.44 | L11: 3412421.4
A12: 21916 | B12: 307028 | F12: 440823.36 | L12: 3500272.6
A13: 22282 | B13: 307100 | C13: 376674.3 | F13: 462627.71 | L13: 3590066.4
A14: 22647 | B14: 323890 | C14: 404653.09 | F14: 494346.88 | L14: 3810123.4
A15: 23012 | B15: 343801 | C15: 426089.3 | F15: 524518.99 | L15: 3976141.9
A16: 23377 | B16: 365113 | C16: 454449.89 | F16: 559046.58 | L16: 4205277.3
A17: 23743 | B17: 383427 | C17: 483158.3 | F17: 586097.63 | L17: 4478555.2
A18: 24108 | B18: 394660 | C18: 515818.3 | F18: 616360.48 | L18: 4773931.2
A19: 24473 | B19: 423046 | C19: 531630.39 | F19: 645956.72 | L19: 4904863.8
A20: 24838 | B20: 445622 | C20: 558255.89 | F20: 675309.49 | L20: 5145914.2
A21: 25204 | B21: 473317 | C21: 586542.89 | F21: 723213.47 | L21: 5306594.5
A22: 25569 | B22: 506241 | C22: 603662.3 | F22: 768053.88 | L22: 5316391.2
A23: 25934 | B23: 525906 | C23: 627922.59 | F23: 808710.41 | L23: 5491445.5
A24: 26299 | B24: 537888 | C24: 662581.8 | F24: 845216.29 | L24: 5780048.2
... A42: 32874 | B42: 927674 | C42: 1159665.9 | F42: 1407121.4 | L42: 10055128
A43: 33239 | B43: 915381 | C43: 1135416.5 | D43: 2062769.6 | F43: 1424522.8 | L43: 10044238
A44: 33604 | B44: 942932 | C44: 1145527.1 | D44: 2104317.6 | F44: 1446119.4 | L44: 10398046
A45: 33970 | B45: 981551 | C45: 1175971.8 | D45: 2083836.2 | F45: 1440927.9 | J45: 13897108 | L45: 10684179
A46: 34335 | B46: 1028145 | C46: 1228820.6 | D46: 2137965.6 | F46: 1475274.7 | I46: 446522296 | J46: 14507764 | L46: 11114646
A47: 34700 | B47: 1060378 | C47: 1261781.6 | D47: 2170150.7 | E47: 720845.19 | F47: 1509276.7 | G47: 1355023 | H47: 1416118.2 | I47: 458270200 | J47: 13650312 | L47: 11413012
A48: 35065 | B48: 1102405 | C48: 1283092.6 | D48: 2192680.2 | E48: 739640.59 | F48: 1530362.5 | G48: 1390010 | H48: 1435173.2 | I48: 472631896 | J48: 14499129 | L48: 11843599
A49: 35431 | B49: 1148781 | C49: 1338011.1 | D49: 2233350.4 | E49: 766173.72 | F49: 1569035.7 | G49: 1458467 | H49: 1462810.7 | I49: 477269496 | J49: 15542903 | L49: 12370300
A50: 35796 | B50: 1206327 | C50: 1390098.3 | D50: 2280165 | E50: 799134.34 | F50: 1623208.2 | G50: 1508263 | H50: 1489205.2 | I50: 471206696 | J50: 16504244 | K50: 760575.66 | L50: 12924876
A51: 36161 | B51: 1256450 | C51: 1461563.3 | D51: 2328735.2 | E51: 834367.1 | F51: 1678386 | G51: 1554509 | H51: 1514194 | I51: 469633096 | J51: 16958941 | K51: 735756.81 | L51: 13543774
A52: 36526 | B52: 1299004 | C52: 1536666.3 | D52: 2395738.7 | E52: 877759.54 | F52: 1747888 | G52: 1621644 | H52: 1572976.5 | I52: 482616896 | J52: 17811854 | K52: 786768.62 | L52: 14096033
A53: 36892 | B53: 1334270 | C53: 1565480.3 | D53: 2434945.9 | E53: 912159.71 | F53: 1781088.5 | G53: 1663462 | H53: 1604537.2 | I53: 484480192 | J53: 17731550 | K53: 741529.42 | L53: 14230726
A54: 37257 | B54: 1387782 | C54: 1612433.1 | D54: 2429386.7 | E54: 937293.87 | F54: 1800106.1 | G54: 1693271 | H54: 1608868.3 | I54: 484683504 | J54: 17689600 | K54: 789341.13 | L54: 14472712
A55: 37622 | B55: 1431076 | C55: 1641559.8 | D55: 2416512.6 | E55: 964843.65 | F55: 1817528 | G55: 1746551 | H55: 1609939.1 | I55: 492124112 | J55: 17899318 | K55: 834832.45 | L55: 14877312
A56: 37987 | B56: 1487804 | C56: 1692322.8 | D56: 2444601.4 | E56: 994894.01 | F56: 1869659.3 | G56: 1788931 | H56: 1633669.9 | I56: 502882400 | J56: 18537508 | K56: 916612.19 | L56: 15449757
A57: 38353 | B57: 1532803 | C57: 1746654.1 | D57: 2466253.2 | E57: 1030224.9 | F57: 1904969 | G57: 1837927 | H57: 1646125.2 | I57: 511954000 | J57: 18929251 | K57: 999036.66 | L57: 15987958
...

Sheet Pop
A1: DATE | B1: POPTOTAUA647NWDB | C1: POPTOTCAA647NWDB | D1: POPTOTDEA647NWDB | E1: POPTOTEEA647NWDB | F1: POPTOTFRA647NWDB | G1: POPTOTGBA647NWDB | H1: POPTOTITA647NWDB | I1: POPTOTJPA647NWDB | J1: POPTOTMXA647NWDB | K1: POPTOTTRA647NWDB | L1: POPTOTUSA647NWDB
A2: 18264
A3: 18629
A4: 18994
A5: 19360
A6: 19725
A7: 20090
A8: 20455
A9: 20821
A10: 21186
A11: 21551
A12: 21916 | B12: 10276477 | C12: 17909356 | D12: 72814900 | E12: 1211537 | F12: 46649927 | G12: 52400000 | H12: 50199700 | I12: 93216000 | J12: 36268055 | K12: 27510980 | L12: 180671000
A13: 22282 | B13: 10483000 | C13: 18271000 | D13: 73377632 | E13: 1225077 | F13: 47161641 | G13: 52800000 | H13: 50536350 | I13: 94055000 | J13: 37439317 | K13: 28255002 | L13: 183691000
A14: 22647 | B14: 10742000 | C14: 18614000 | D14: 74025784 | E14: 1241623 | F14: 47679792 | G14: 53250000 | H14: 50879450 | I14: 94933000 | J14: 38683283 | K14: 29033647 | L14: 186538000
A15: 23012 | B15: 10950000 | C15: 18964000 | D15: 74714353 | E15: 1258857 | F15: 48189939 | G15: 53650000 | H15: 51252000 | I15: 95900000 | J15: 39982118 | K15: 29827877 | L15: 189242000
A16: 23377 | B16: 11167000 | C16: 19325000 | D16: 75318337 | E16: 1277086 | F16: 48733997 | G16: 54000000 | H16: 51675350 | I16: 96903000 | J16: 41333878 | K16: 30612821 | L16: 191889000
A17: 23743 | B17: 11388000 | C17: 19678000 | D17: 75963695 | E17: 1294566 | F17: 49282756 | G17: 54348050 | H17: 52112350 | I17: 97952000 | J17: 42737991 | K17: 31374536 | L17: 194303000
A18: 24108 | B18: 11651000 | C18: 20048000 | D18: 76600311 | E18: 1308597 | F18: 49817041 | G18: 54648500 | H18: 52519000 | I18: 98851000 | J18: 44180437 | K18: 32172785 | L18: 196560000
A19: 24473 | B19: 11799000 | C19: 20412000 | D19: 76951336 | E19: 1318946 | F19: 50334012 | G19: 54943600 | H19: 52900500 | I19: 99879000 | J19: 45656963 | K19: 33026490 | L19: 198712000
A20: 24838 | B20: 12009000 | C20: 20744000 | D20: 77294314 | E20: 1331214 | F20: 50817020 | G20: 55211700 | H20: 53235750 | I20: 101011000 | J20: 47170337 | K20: 33884075 | L20: 200706000
A21: 25204 | B21: 12263000 | C21: 21028000 | D21: 77909682 | E21: 1345249 | F21: 51272683 | G21: 55441750 | H21: 53537950 | I21: 102219000 | J21: 48714394 | K21: 34721990 | L21: 202677000
A22: 25569 | B22: 12507000 | C22: 21324000 | D22: 78169289 | E22: 1360076 | F22: 51724116 | G22: 55663250 | H22: 53821850 | I22: 103403000 | J22: 50289306 | K22: 35540990 | L22: 205052000
A23: 25934 | B23: 12937000 | C23: 21962032 | D23: 78312842 | E23: 1376955 | F23: 52185222 | G23: 55896223 | H23: 54073490 | I23: 105697000 | J23: 51897675 | K23: 36359957 | L23: 207661000
... A75: 44927 | B75: 26638544 | C75: 40097761 | D75: 84482267 | E75: 1366188 | F75: 68170228 | G75: 68350000 | H75: 58761146 | I75: 124516650 | J75: 128455567 | K75: 85326000 | L75: 334914895

Sheet TFP
A1: DATE | B1: A_Australia | C1: A_Canada | D1: A_Germany | E1: A_Estonia | F1: A_France | G1: A_GB | H1: A_Italy | I1: A_Japan | J1: A_Mexico | K1: A_Turkey | L1: A_US
A2: 18264 | B2: =IF(GDP!B2=0,"",GDP!B2/('Capital Est'!B2^(1/3)*Pop!B2^(2/3))) | C2: =IF(GDP!C2=0,"",GDP!C2/('Capital Est'!C2^(1/3)*Pop!C2^(2/3))) | D2: =IF(GDP!D2=0,"",GDP!D2/('Capital Est'!D2^(1/3)*Pop!D2^(2/3))) | E2: =IF(GDP!E2=0,"",GDP!E2/('Capital Est'!E2^(1/3)*Pop!E2^(2/3))) | G2: =IF(GDP!G2=0,"",GDP!G2/('Capital Est'!G2^(1/3)*Pop!G2^(2/3))) | H2: =IF(GDP!H2=0,"",GDP!H2/('Capital Est'!H2^(1/3)*Pop!H2^(2/3))) | I2: =IF(GDP!I2=0,"",GDP!I2/('Capital Est'!I2^(1/3)*Pop!I2^(2/3))) | J2: =IF(GDP!J2=0,"",GDP!J2/('Capital Est'!J2^(1/3)*Pop!J2^(2/3))) | K2: =IF(GDP!K2=0,"",GDP!K2/('Capital Est'!K2^(1/3)*Pop!K2^(2/3)))
A3: 18629 | B3: =IF(GDP!B3=0,"",GDP!B3/('Capital Est'!B3^(1/3)*Pop!B3^(2/3))) | C3: =IF(GDP!C3=0,"",GDP!C3/('Capital Est'!C3^(1/3)*Pop!C3^(2/3))) | D3: =IF(GDP!D3=0,"",GDP!D3/('Capital Est'!D3^(1/3)*Pop!D3^(2/3))) | E3: =IF(GDP!E3=0,"",GDP!E3/('Capital Est'!E3^(1/3)*Pop!E3^(2/3))) | G3: =IF(GDP!G3=0,"",GDP!G3/('Capital Est'!G3^(1/3)*Pop!G3^(2/3))) | H3: =IF(GDP!H3=0,"",GDP!H3/('Capital Est'!H3^(1/3)*Pop!H3^(2/3))) | I3: =IF(GDP!I3=0,"",GDP!I3/('Capital Est'!I3^(1/3)*Pop!I3^(2/3))) | J3: =IF(GDP!J3=0,"",GDP!J3/('Capital Est'!J3^(1/3)*Pop!J3^(2/3))) | K3: =IF(GDP!K3=0,"",GDP!K3/('Capital Est'!K3^(1/3)*Pop!K3^(2/3)))
A4: 18994 | B4: =IF(GDP!B4=0,"",GDP!B4/('Capital Est'!B4^(1/3)*Pop!B4^(2/3))) | C4: =IF(GDP!C4=0,"",GDP!C4/('Capital Est'!C4^(1/3)*Pop!C4^(2/3))) | D4: =IF(GDP!D4=0,"",GDP!D4/('Capital Est'!D4^(1/3)*Pop!D4^(2/3))) | E4: =IF(GDP!E4=0,"",GDP!E4/('Capital Est'!E4^(1/3)*Pop!E4^(2/3))) | G4: =IF(GDP!G4=0,"",GDP!G4/('Capital Est'!G4^(1/3)*Pop!G4^(2/3))) | H4: =IF(GDP!H4=0,"",GDP!H4/('Capital Est'!H4^(1/3)*Pop!H4^(2/3))) | I4: =IF(GDP!I4=0,"",GDP!I4/('Capital Est'!I4^(1/3)*Pop!I4^(2/3))) | J4: =IF(GDP!J4=0,"",GDP!J4/('Capital Est'!J4^(1/3)*Pop!J4^(2/3))) | K4: =IF(GDP!K4=0,"",GDP!K4/('Capital Est'!K4^(1/3)*Pop!K4^(2/3)))
A5: 19360 | B5: =IF(GDP!B5=0,"",GDP!B5/('Capital Est'!B5^(1/3)*Pop!B5^(2/3))) | C5: =IF(GDP!C5=0,"",GDP!C5/('Capital Est'!C5^(1/3)*Pop!C5^(2/3))) | D5: =IF(GDP!D5=0,"",GDP!D5/('Capital Est'!D5^(1/3)*Pop!D5^(2/3))) | E5: =IF(GDP!E5=0,"",GDP!E5/('Capital Est'!E5^(1/3)*Pop!E5^(2/3))) | G5: =IF(GDP!G5=0,"",GDP!G5/('Capital Est'!G5^(1/3)*Pop!G5^(2/3))) | H5: =IF(GDP!H5=0,"",GDP!H5/('Capital Est'!H5^(1/3)*Pop!H5^(2/3))) | I5: =IF(GDP!I5=0,"",GDP!I5/('Capital Est'!I5^(1/3)*Pop!I5^(2/3))) | J5: =IF(GDP!J5=0,"",GDP!J5/('Capital Est'!J5^(1/3)*Pop!J5^(2/3))) | K5: =IF(GDP!K5=0,"",GDP!K5/('Capital Est'!K5^(1/3)*Pop!K5^(2/3)))
A6: 19725 | B6: =IF(GDP!B6=0,"",GDP!B6/('Capital Est'!B6^(1/3)*Pop!B6^(2/3))) | C6: =IF(GDP!C6=0,"",GDP!C6/('Capital Est'!C6^(1/3)*Pop!C6^(2/3))) | D6: =IF(GDP!D6=0,"",GDP!D6/('Capital Est'!D6^(1/3)*Pop!D6^(2/3))) | E6: =IF(GDP!E6=0,"",GDP!E6/('Capital Est'!E6^(1/3)*Pop!E6^(2/3))) | G6: =IF(GDP!G6=0,"",GDP!G6/('Capital Est'!G6^(1/3)*Pop!G6^(2/3))) | H6: =IF(GDP!H6=0,"",GDP!H6/('Capital Est'!H6^(1/3)*Pop!H6^(2/3))) | I6: =IF(GDP!I6=0,"",GDP!I6/('Capital Est'!I6^(1/3)*Pop!I6^(2/3))) | J6: =IF(GDP!J6=0,"",GDP!J6/('Capital Est'!J6^(1/3)*Pop!J6^(2/3))) | K6: =IF(GDP!K6=0,"",GDP!K6/('Capital Est'!K6^(1/3)*Pop!K6^(2/3)))
A7: 20090 | B7: =IF(GDP!B7=0,"",GDP!B7/('Capital Est'!B7^(1/3)*Pop!B7^(2/3))) | C7: =IF(GDP!C7=0,"",GDP!C7/('Capital Est'!C7^(1/3)*Pop!C7^(2/3))) | D7: =IF(GDP!D7=0,"",GDP!D7/('Capital Est'!D7^(1/3)*Pop!D7^(2/3))) | E7: =IF(GDP!E7=0,"",GDP!E7/('Capital Est'!E7^(1/3)*Pop!E7^(2/3))) | G7: =IF(GDP!G7=0,"",GDP!G7/('Capital Est'!G7^(1/3)*Pop!G7^(2/3))) | H7: =IF(GDP!H7=0,"",GDP!H7/('Capital Est'!H7^(1/3)*Pop!H7^(2/3))) | I7: =IF(GDP!I7=0,"",GDP!I7/('Capital Est'!I7^(1/3)*Pop!I7^(2/3))) | J7: =IF(GDP!J7=0,"",GDP!J7/('Capital Est'!J7^(1/3)*Pop!J7^(2/3))) | K7: =IF(GDP!K7=0,"",GDP!K7/('Capital Est'!K7^(1/3)*Pop!K7^(2/3)))
A8: 20455 | B8: =IF(GDP!B8=0,"",GDP!B8/('Capital Est'!B8^(1/3)*Pop!B8^(2/3))) | C8: =IF(GDP!C8=0,"",GDP!C8/('Capital Est'!C8^(1/3)*Pop!C8^(2/3))) | D8: =IF(GDP!D8=0,"",GDP!D8/('Capital Est'!D8^(1/3)*Pop!D8^(2/3))) | E8: =IF(GDP!E8=0,"",GDP!E8/('Capital Est'!E8^(1/3)*Pop!E8^(2/3))) | G8: =IF(GDP!G8=0,"",GDP!G8/('Capital Est'!G8^(1/3)*Pop!G8^(2/3))) | H8: =IF(GDP!H8=0,"",GDP!H8/('Capital Est'!H8^(1/3)*Pop!H8^(2/3))) | I8: =IF(GDP!I8=0,"",GDP!I8/('Capital Est'!I8^(1/3)*Pop!I8^(2/3))) | J8: =IF(GDP!J8=0,"",GDP!J8/('Capital Est'!J8^(1/3)*Pop!J8^(2/3))) | K8: =IF(GDP!K8=0,"",GDP!K8/('Capital Est'!K8^(1/3)*Pop!K8^(2/3)))
A9: 20821 | B9: =IF(GDP!B9=0,"",GDP!B9/('Capital Est'!B9^(1/3)*Pop!B9^(2/3))) | C9: =IF(GDP!C9=0,"",GDP!C9/('Capital Est'!C9^(1/3)*Pop!C9^(2/3))) | D9: =IF(GDP!D9=0,"",GDP!D9/('Capital Est'!D9^(1/3)*Pop!D9^(2/3))) | E9: =IF(GDP!E9=0,"",GDP!E9/('Capital Est'!E9^(1/3)*Pop!E9^(2/3))) | G9: =IF(GDP!G9=0,"",GDP!G9/('Capital Est'!G9^(1/3)*Pop!G9^(2/3))) | H9: =IF(GDP!H9=0,"",GDP!H9/('Capital Est'!H9^(1/3)*Pop!H9^(2/3))) | I9: =IF(GDP!I9=0,"",GDP!I9/('Capital Est'!I9^(1/3)*Pop!I9^(2/3))) | J9: =IF(GDP!J9=0,"",GDP!J9/('Capital Est'!J9^(1/3)*Pop!J9^(2/3))) | K9: =IF(GDP!K9=0,"",GDP!K9/('Capital Est'!K9^(1/3)*Pop!K9^(2/3)))
A10: 21186 | B10: =IF(GDP!B10=0,"",GDP!B10/('Capital Est'!B10^(1/3)*Pop!B10^(2/3))) | C10: =IF(GDP!C10=0,"",GDP!C10/('Capital Est'!C10^(1/3)*Pop!C10^(2/3))) | D10: =IF(GDP!D10=0,"",GDP!D10/('Capital Est'!D10^(1/3)*Pop!D10^(2/3))) | E10: =IF(GDP!E10=0,"",GDP!E10/('Capital Est'!E10^(1/3)*Pop!E10^(2/3))) | G10: =IF(GDP!G10=0,"",GDP!G10/('Capital Est'!G10^(1/3)*Pop!G10^(2/3))) | H10: =IF(GDP!H10=0,"",GDP!H10/('Capital Est'!H10^(1/3)*Pop!H10^(2/3))) | I10: =IF(GDP!I10=0,"",GDP!I10/('Capital Est'!I10^(1/3)*Pop!I10^(2/3))) | J10: =IF(GDP!J10=0,"",GDP!J10/('Capital Est'!J10^(1/3)*Pop!J10^(2/3))) | K10: =IF(GDP!K10=0,"",GDP!K10/('Capital Est'!K10^(1/3)*Pop!K10^(2/3)))
A11: 21551 | B11: =IF(GDP!B11=0,"",GDP!B11/('Capital Est'!B11^(1/3)*Pop!B11^(2/3))) | C11: =IF(GDP!C11=0,"",GDP!C11/('Capital Est'!C11^(1/3)*Pop!C11^(2/3))) | D11: =IF(GDP!D11=0,"",GDP!D11/('Capital Est'!D11^(1/3)*Pop!D11^(2/3))) | E11: =IF(GDP!E11=0,"",GDP!E11/('Capital Est'!E11^(1/3)*Pop!E11^(2/3))) | G11: =IF(GDP!G11=0,"",GDP!G11/('Capital Est'!G11^(1/3)*Pop!G11^(2/3))) | H11: =IF(GDP!H11=0,"",GDP!H11/('Capital Est'!H11^(1/3)*Pop!H11^(2/3))) | I11: =IF(GDP!I11=0,"",GDP!I11/('Capital Est'!I11^(1/3)*Pop!I11^(2/3))) | J11: =IF(GDP!J11=0,"",GDP!J11/('Capital Est'!J11^(1/3)*Pop!J11^(2/3))) | K11: =IF(GDP!K11=0,"",GDP!K11/('Capital Est'!K11^(1/3)*Pop!K11^(2/3)))
A12: 21916 | B12: =IF(GDP!B12=0,"",GDP!B12/('Capital Est'!B12^(1/3)*Pop!B12^(2/3))) -> 0.066519001 | C12: =IF(GDP!C12=0,"",GDP!C12/('Capital Est'!C12^(1/3)*Pop!C12^(2/3))) | D12: =IF(GDP!D12=0,"",GDP!D12/('Capital Est'!D12^(1/3)*Pop!D12^(2/3))) | E12: =IF(GDP!E12=0,"",GDP!E12/('Capital Est'!E12^(1/3)*Pop!E12^(2/3))) | F12: =IF(GDP!F12=0,"",GDP!F12/('Capital Est'!F12^(1/3)*Pop!F12^(2/3))) -> 0.031083264 | G12: =IF(GDP!G12=0,"",GDP!G12/('Capital Est'!G12^(1/3)*Pop!G12^(2/3))) | H12: =IF(GDP!H12=0,"",GDP!H12/('Capital Est'!H12^(1/3)*Pop!H12^(2/3))) | I12: =IF(GDP!I12=0,"",GDP!I12/('Capital Est'!I12^(1/3)*Pop!I12^(2/3))) | ... K12: =IF(GDP!K12=0,"",GDP!K12/('Capital Est'!K12^(1/3)*Pop!K12^(2/3)))
A13: 22282 | B13: =IF(GDP!B13=0,"",GDP!B13/('Capital Est'!B13^(1/3)*Pop!B13^(2/3))) -> 0.065364104 | C13: =IF(GDP!C13=0,"",GDP!C13/('Capital Est'!C13^(1/3)*Pop!C13^(2/3))) -> 0.051793966 | D13: =IF(GDP!D13=0,"",GDP!D13/('Capital Est'!D13^(1/3)*Pop!D13^(2/3))) | E13: =IF(GDP!E13=0,"",GDP!E13/('Capital Est'!E13^(1/3)*Pop!E13^(2/3))) | F13: =IF(GDP!F13=0,"",GDP!F13/('Capital Est'!F13^(1/3)*Pop!F13^(2/3))) -> 0.03194925 | G13: =IF(GDP!G13=0,"",GDP!G13/('Capital Est'!G13^(1/3)*Pop!G13^(2/3))) | H13: =IF(GDP!H13=0,"",GDP!H13/('Capital Est'!H13^(1/3)*Pop!H13^(2/3))) | I13: =IF(GDP!I13=0,"",GDP!I13/('Capital Est'!I13^(1/3)*Pop!I13^(2/3))) | ... K13: =IF(GDP!K13=0,"",GDP!K13/('Capital Est'!K13^(1/3)*Pop!K13^(2/3)))
A14: 22647 | B14: =IF(GDP!B14=0,"",GDP!B14/('Capital Est'!B14^(1/3)*Pop!B14^(2/3))) -> 0.067525271 | C14: =IF(GDP!C14=0,"",GDP!C14/('Capital Est'!C14^(1/3)*Pop!C14^(2/3))) -> 0.054569066 | D14: =IF(GDP!D14=0,"",GDP!D14/('Capital Est'!D14^(1/3)*Pop!D14^(2/3))) | E14: =IF(GDP!E14=0,"",GDP!E14/('Capital Est'!E14^(1/3)*Pop!E14^(2/3))) | F14: =IF(GDP!F14=0,"",GDP!F14/('Capital Est'!F14^(1/3)*Pop!F14^(2/3))) -> 0.033414088 | G14: =IF(GDP!G14=0,"",GDP!G14/('Capital Est'!G14^(1/3)*Pop!G14^(2/3))) | H14: =IF(GDP!H14=0,"",GDP!H14/('Capital Est'!H14^(1/3)*Pop!H14^(2/3))) | I14: =IF(GDP!I14=0,"",GDP!I14/('Capital Est'!I14^(1/3)*Pop!I14^(2/3))) | ... K14: =IF(GDP!K14=0,"",GDP!K14/('Capital Est'!K14^(1/3)*Pop!K14^(2/3)))
A15: 23012 | B15: =IF(GDP!B15=0,"",GDP!B15/('Capital Est'!B15^(1/3)*Pop!B15^(2/3))) -> 0.070351824 | C15: =IF(GDP!C15=0,"",GDP!C15/('Capital Est'!C15^(1/3)*Pop!C15^(2/3))) -> 0.056334203 | D15: =IF(GDP!D15=0,"",GDP!D15/('Capital Est'!D15^(1/3)*Pop!D15^(2/3))) | E15: =IF(GDP!E15=0,"",GDP!E15/('Capital Est'!E15^(1/3)*Pop!E15^(2/3))) | F15: =IF(GDP!F15=0,"",GDP!F15/('Capital Est'!F15^(1/3)*Pop!F15^(2/3))) -> 0.034672162 | G15: =IF(GDP!G15=0,"",GDP!G15/('Capital Est'!G15^(1/3)*Pop!G15^(2/3))) | H15: =IF(GDP!H15=0,"",GDP!H15/('Capital Est'!H15^(1/3)*Pop!H15^(2/3))) | I15: =IF(GDP!I15=0,"",GDP!I15/('Capital Est'!I15^(1/3)*Pop!I15^(2/3))) | ... K15: =IF(GDP!K15=0,"",GDP!K15/('Capital Est'!K15^(1/3)*Pop!K15^(2/3)))
A16: 23377 | B16: =IF(GDP!B16=0,"",GDP!B16/('Capital Est'!B16^(1/3)*Pop!B16^(2/3))) -> 0.073221555 | C16: =IF(GDP!C16=0,"",GDP!C16/('Capital Est'!C16^(1/3)*Pop!C16^(2/3))) -> 0.05877106 | D16: =IF(GDP!D16=0,"",GDP!D16/('Capital Est'!D16^(1/3)*Pop!D16^(2/3))) | E16: =IF(GDP!E16=0,"",GDP!E16/('Capital Est'!E16^(1/3)*Pop!E16^(2/3))) | F16: =IF(GDP!F16=0,"",GDP!F16/('Capital Est'!F16^(1/3)*Pop!F16^(2/3))) -> 0.03607228 | G16: =IF(GDP!G16=0,"",GDP!G16/('Capital Est'!G16^(1/3)*Pop!G16^(2/3))) | H16: =IF(GDP!H16=0,"",GDP!H16/('Capital Est'!H16^(1/3)*Pop!H16^(2/3))) | I16: =IF(GDP!I16=0,"",GDP!I16/('Capital Est'!I16^(1/3)*Pop!I16^(2/3))) | ... K16: =IF(GDP!K16=0,"",GDP!K16/('Capital Est'!K16^(1/3)*Pop!K16^(2/3)))
A17: 23743 | B17: =IF(GDP!B17=0,"",GDP!B17/('Capital Est'!B17^(1/3)*Pop!B17^(2/3))) -> 0.075266962 | C17: =IF(GDP!C17=0,"",GDP!C17/('Capital Est'!C17^(1/3)*Pop!C17^(2/3))) -> 0.061044017 | D17: =IF(GDP!D17=0,"",GDP!D17/('Capital Est'!D17^(1/3)*Pop!D17^(2/3))) | E17: =IF(GDP!E17=0,"",GDP!E17/('Capital Est'!E17^(1/3)*Pop!E17^(2/3))) | F17: =IF(GDP!F17=0,"",GDP!F17/('Capital Est'!F17^(1/3)*Pop!F17^(2/3))) -> 0.036910019 | G17: =IF(GDP!G17=0,"",GDP!G17/('Capital Est'!G17^(1/3)*Pop!G17^(2/3))) | H17: =IF(GDP!H17=0,"",GDP!H17/('Capital Est'!H17^(1/3)*Pop!H17^(2/3))) | I17: =IF(GDP!I17=0,"",GDP!I17/('Capital Est'!I17^(1/3)*Pop!I17^(2/3))) | ... K17: =IF(GDP!K17=0,"",GDP!K17/('Capital Est'!K17^(1/3)*Pop!K17^(2/3)))
A18: 24108 | B18: =IF(GDP!B18=0,"",GDP!B18/('Capital Est'!B18^(1/3)*Pop!B18^(2/3))) -> 0.075621525 | C18: =IF(GDP!C18=0,"",GDP!C18/('Capital Est'!C18^(1/3)*Pop!C18^(2/3))) -> 0.063534722 | D18: =IF(GDP!D18=0,"",GDP!D18/('Capital Est'!D18^(1/3)*Pop!D18^(2/3))) | E18: =IF(GDP!E18=0,"",GDP!E18/('Capital Est'!E18^(1/3)*Pop!E18^(2/3))) | F18: =IF(GDP!F18=0,"",GDP!F18/('Capital Est'!F18^(1/3)*Pop!F18^(2/3))) -> 0.037870191 | G18: =IF(GDP!G18=0,"",GDP!G18/('Capital Est'!G18^(1/3)*Pop!G18^(2/3))) | H18: =IF(GDP!H18=0,"",GDP!H18/('Capital Est'!H18^(1/3)*Pop!H18^(2/3))) | I18: =IF(GDP!I18=0,"",GDP!I18/('Capital Est'!I18^(1/3)*Pop!I18^(2/3))) | ... K18: =IF(GDP!K18=0,"",GDP!K18/('Capital Est'!K18^(1/3)*Pop!K18^(2/3)))
A19: 24473 | B19: =IF(GDP!B19=0,"",GDP!B19/('Capital Est'!B19^(1/3)*Pop!B19^(2/3))) -> 0.079607291 | C19: =IF(GDP!C19=0,"",GDP!C19/('Capital Est'!C19^(1/3)*Pop!C19^(2/3))) -> 0.06392692 | D19: =IF(GDP!D19=0,"",GDP!D19/('Capital Est'!D19^(1/3)*Pop!D19^(2/3))) | E19: =IF(GDP!E19=0,"",GDP!E19/('Capital Est'!E19^(1/3)*Pop!E19^(2/3))) | F19: =IF(GDP!F19=0,"",GDP!F19/('Capital Est'!F19^(1/3)*Pop!F19^(2/3))) -> 0.038711953 | G19: =IF(GDP!G19=0,"",GDP!G19/('Capital Est'!G19^(1/3)*Pop!G19^(2/3))) | H19: =IF(GDP!H19=0,"",GDP!H19/('Capital Est'!H19^(1/3)*Pop!H19^(2/3))) | I19: =IF(GDP!I19=0,"",GDP!I19/('Capital Est'!I19^(1/3)*Pop!I19^(2/3))) | ... K19: =IF(GDP!K19=0,"",GDP!K19/('Capital Est'!K19^(1/3)*Pop!K19^(2/3)))
A20: 24838 | B20: =IF(GDP!B20=0,"",GDP!B20/('Capital Est'!B20^(1/3)*Pop!B20^(2/3))) -> 0.081988342 | C20: =IF(GDP!C20=0,"",GDP!C20/('Capital Est'!C20^(1/3)*Pop!C20^(2/3))) -> 0.065659504 | D20: =IF(GDP!D20=0,"",GDP!D20/('Capital Est'!D20^(1/3)*Pop!D20^(2/3))) | E20: =IF(GDP!E20=0,"",GDP!E20/('Capital Est'!E20^(1/3)*Pop!E20^(2/3))) | F20: =IF(GDP!F20=0,"",GDP!F20/('Capital Est'!F20^(1/3)*Pop!F20^(2/3))) -> 0.039495718 | G20: =IF(GDP!G20=0,"",GDP!G20/('Capital Est'!G20^(1/3)*Pop!G20^(2/3))) | H20: =IF(GDP!H20=0,"",GDP!H20/('Capital Est'!H20^(1/3)*Pop!H20^(2/3))) | I20: =IF(GDP!I20=0,"",GDP!I20/('Capital Est'!I20^(1/3)*Pop!I20^(2/3))) | ... K20: =IF(GDP!K20=0,"",GDP!K20/('Capital Est'!K20^(1/3)*Pop!K20^(2/3)))
A21: 25204 | B21: =IF(GDP!B21=0,"",GDP!B21/('Capital Est'!B21^(1/3)*Pop!B21^(2/3))) -> 0.084934392 | C21: =IF(GDP!C21=0,"",GDP!C21/('Capital Est'!C21^(1/3)*Pop!C21^(2/3))) -> 0.067570089 | D21: =IF(GDP!D21=0,"",GDP!D21/('Capital Est'!D21^(1/3)*Pop!D21^(2/3))) | E21: =IF(GDP!E21=0,"",GDP!E21/('Capital Est'!E21^(1/3)*Pop!E21^(2/3))) | F21: =IF(GDP!F21=0,"",GDP!F21/('Capital Est'!F21^(1/3)*Pop!F21^(2/3))) -> 0.041270987 | G21: =IF(GDP!G21=0,"",GDP!G21/('Capital Est'!G21^(1/3)*Pop!G21^(2/3))) | H21: =IF(GDP!H21=0,"",GDP!H21/('Capital Est'!H21^(1/3)*Pop!H21^(2/3))) | I21: =IF(GDP!I21=0,"",GDP!I21/('Capital Est'!I21^(1/3)*Pop!I21^(2/3))) | ... K21: =IF(GDP!K21=0,"",GDP!K21/('Capital Est'!K21^(1/3)*Pop!K21^(2/3)))
A22: 25569 | B22: =IF(GDP!B22=0,"",GDP!B22/('Capital Est'!B22^(1/3)*Pop!B22^(2/3))) -> 0.088690071 | C22: =IF(GDP!C22=0,"",GDP!C22/('Capital Est'!C22^(1/3)*Pop!C22^(2/3))) -> 0.06814527 | D22: =IF(GDP!D22=0,"",GDP!D22/('Capital Est'!D22^(1/3)*Pop!D22^(2/3))) | E22: =IF(GDP!E22=0,"",GDP!E22/('Capital Est'!E22^(1/3)*Pop!E22^(2/3))) | F22: =IF(GDP!F22=0,"",GDP!F22/('Capital Est'!F22^(1/3)*Pop!F22^(2/3))) -> 0.042774711 | G22: =IF(GDP!G22=0,"",GDP!G22/('Capital Est'!G22^(1/3)*Pop!G22^(2/3))) | H22: =IF(GDP!H22=0,"",GDP!H22/('Capital Est'!H22^(1/3)*Pop!H22^(2/3))) | I22: =IF(GDP!I22=0,"",GDP!I22/('Capital Est'!I22^(1/3)*Pop!I22^(2/3))) | ... K22: =IF(GDP!K22=0,"",GDP!K22/('Capital Est'!K22^(1/3)*Pop!K22^(2/3)))
A23: 25934 | B23: =IF(GDP!B23=0,"",GDP!B23/('Capital Est'!B23^(1/3)*Pop!B23^(2/3))) -> 0.089078177 | C23: =IF(GDP!C23=0,"",GDP!C23/('Capital Est'!C23^(1/3)*Pop!C23^(2/3))) -> 0.068684204 | D23: =IF(GDP!D23=0,"",GDP!D23/('Capital Est'!D23^(1/3)*Pop!D23^(2/3))) | E23: =IF(GDP!E23=0,"",GDP!E23/('Capital Est'!E23^(1/3)*Pop!E23^(2/3))) | F23: =IF(GDP!F23=0,"",GDP!F23/('Capital Est'!F23^(1/3)*Pop!F23^(2/3))) -> 0.04393881 | G23: =IF(GDP!G23=0,"",GDP!G23/('Capital Est'!G23^(1/3)*Pop!G23^(2/3))) | H23: =IF(GDP!H23=0,"",GDP!H23/('Capital Est'!H23^(1/3)*Pop!H23^(2/3))) | I23: =IF(GDP!I23=0,"",GDP!I23/('Capital Est'!I23^(1/3)*Pop!I23^(2/3))) | ... L23: =IF(GDP!L23=0,"",GDP!L23/('Capital Est'!L23^(1/3)*Pop!L23^(2/3))) -> 0.061543294
A24: 26299 | B24: =IF(GDP!B24=0,"",GDP!B24/('Capital Est'!B24^(1/3)*Pop!B24^(2/3))) -> 0.089059546 | C24: =IF(GDP!C24=0,"",GDP!C24/('Capital Est'!C24^(1/3)*Pop!C24^(2/3))) -> 0.071059545 | D24: =IF(GDP!D24=0,"",GDP!D24/('Capital Est'!D24^(1/3)*Pop!D24^(2/3))) | E24: =IF(GDP!E24=0,"",GDP!E24/('Capital Est'!E24^(1/3)*Pop!E24^(2/3))) | F24: =IF(GDP!F24=0,"",GDP!F24/('Capital Est'!F24^(1/3)*Pop!F24^(2/3))) -> 0.044808099 | G24: =IF(GDP!G24=0,"",GDP!G24/('Capital Est'!G24^(1/3)*Pop!G24^(2/3))) | H24: =IF(GDP!H24=0,"",GDP!H24/('Capital Est'!H24^(1/3)*Pop!H24^(2/3))) | I24: =IF(GDP!I24=0,"",GDP!I24/('Capital Est'!I24^(1/3)*Pop!I24^(2/3))) | ... L24: =IF(GDP!L24=0,"",GDP!L24/('Capital Est'!L24^(1/3)*Pop!L24^(2/3))) -> 0.063914833
A25: 26665 | B25: =IF(GDP!B25=0,"",GDP!B25/('Capital Est'!B25^(1/3)*Pop!B25^(2/3))) -> 0.090981391 | C25: =IF(GDP!C25=0,"",GDP!C25/('Capital Est'!C25^(1/3)*Pop!C25^(2/3))) -> 0.074248676 | D25: =IF(GDP!D25=0,"",GDP!D25/('Capital Est'!D25^(1/3)*Pop!D25^(2/3))) | E25: =IF(GDP!E25=0,"",GDP!E25/('Capital Est'!E25^(1/3)*Pop!E25^(2/3))) | F25: =IF(GDP!F25=0,"",GDP!F25/('Capital Est'!F25^(1/3)*Pop!F25^(2/3))) -> 0.04643981 | G25: =IF(GDP!G25=0,"",GDP!G25/('Capital Est'!G25^(1/3)*Pop!G25^(2/3))) | H25: =IF(GDP!H25=0,"",GDP!H25/('Capital Est'!H25^(1/3)*Pop!H25^(2/3))) | I25: =IF(GDP!I25=0,"",GDP!I25/('Capital Est'!I25^(1/3)*Pop!I25^(2/3))) | ... L25: =IF(GDP!L25=0,"",GDP!L25/('Capital Est'!L25^(1/3)*Pop!L25^(2/3))) -> 0.066610124
A26: 27030 | B26: =IF(GDP!B26=0,"",GDP!B26/('Capital Est'!B26^(1/3)*Pop!B26^(2/3))) -> 0.090026672 | C26: =IF(GDP!C26=0,"",GDP!C26/('Capital Est'!C26^(1/3)*Pop!C26^(2/3))) -> 0.075018291 | D26: =IF(GDP!D26=0,"",GDP!D26/('Capital Est'!D26^(1/3)*Pop!D26^(2/3))) | E26: =IF(GDP!E26=0,"",GDP!E26/('Capital Est'!E26^(1/3)*Pop!E26^(2/3))) | F26: =IF(GDP!F26=0,"",GDP!F26/('Capital Est'!F26^(1/3)*Pop!F26^(2/3))) -> 0.047408738 | G26: =IF(GDP!G26=0,"",GDP!G26/('Capital Est'!G26^(1/3)*Pop!G26^(2/3))) | H26: =IF(GDP!H26=0,"",GDP!H26/('Capital Est'!H26^(1/3)*Pop!H26^(2/3))) | I26: =IF(GDP!I26=0,"",GDP!I26/('Capital Est'!I26^(1/3)*Pop!I26^(2/3))) | ... L26: =IF(GDP!L26=0,"",GDP!L26/('Capital Est'!L26^(1/3)*Pop!L26^(2/3))) -> 0.065451065
A27: 27395 | B27: =IF(GDP!B27=0,"",GDP!B27/('Capital Est'!B27^(1/3)*Pop!B27^(2/3))) -> 0.090712056 | C27: =IF(GDP!C27=0,"",GDP!C27/('Capital Est'!C27^(1/3)*Pop!C27^(2/3))) -> 0.074432687 | D27: =IF(GDP!D27=0,"",GDP!D27/('Capital Est'!D27^(1/3)*Pop!D27^(2/3))) | E27: =IF(GDP!E27=0,"",GDP!E27/('Capital Est'!E27^(1/3)*Pop!E27^(2/3))) | F27: =IF(GDP!F27=0,"",GDP!F27/('Capital Est'!F27^(1/3)*Pop!F27^(2/3))) -> 0.046090301 | G27: =IF(GDP!G27=0,"",GDP!G27/('Capital Est'!G27^(1/3)*Pop!G27^(2/3))) | H27: =IF(GDP!H27=0,"",GDP!H27/('Capital Est'!H27^(1/3)*Pop!H27^(2/3))) | I27: =IF(GDP!I27=0,"",GDP!I27/('Capital Est'!I27^(1/3)*Pop!I27^(2/3))) | ... L27: =IF(GDP!L27=0,"",GDP!L27/('Capital Est'!L27^(1/3)*Pop!L27^(2/3))) -> 0.064608363
A28: 27760 | B28: =IF(GDP!B28=0,"",GDP!B28/('Capital Est'!B28^(1/3)*Pop!B28^(2/3))) -> 0.0927218 | C28: =IF(GDP!C28=0,"",GDP!C28/('Capital Est'!C28^(1/3)*Pop!C28^(2/3))) -> 0.077040601 | D28: =IF(GDP!D28=0,"",GDP!D28/('Capital Est'!D28^(1/3)*Pop!D28^(2/3))) | E28: =IF(GDP!E28=0,"",GDP!E28/('Capital Est'!E28^(1/3)*Pop!E28^(2/3))) | F28: =IF(GDP!F28=0,"",GDP!F28/('Capital Est'!F28^(1/3)*Pop!F28^(2/3))) -> 0.04725697 | G28: =IF(GDP!G28=0,"",GDP!G28/('Capital Est'!G28^(1/3)*Pop!G28^(2/3))) | H28: =IF(GDP!H28=0,"",GDP!H28/('Capital Est'!H28^(1/3)*Pop!H28^(2/3))) | I28: =IF(GDP!I28=0,"",GDP!I28/('Capital Est'!I28^(1/3)*Pop!I28^(2/3))) | ... L28: =IF(GDP!L28=0,"",GDP!L28/('Capital Est'!L28^(1/3)*Pop!L28^(2/3))) -> 0.067289436
A29: 28126 | B29: =IF(GDP!B29=0,"",GDP!B29/('Capital Est'!B29^(1/3)*Pop!B29^(2/3))) -> 0.092549285 | C29: =IF(GDP!C29=0,"",GDP!C29/('Capital Est'!C29^(1/3)*Pop!C29^(2/3))) -> 0.078079478 | D29: =IF(GDP!D29=0,"",GDP!D29/('Capital Est'!D29^(1/3)*Pop!D29^(2/3))) | E29: =IF(GDP!E29=0,"",GDP!E29/('Capital Est'!E29^(1/3)*Pop!E29^(2/3))) | F29: =IF(GDP!F29=0,"",GDP!F29/('Capital Est'!F29^(1/3)*Pop!F29^(2/3))) -> 0.048150473 | G29: =IF(GDP!G29=0,"",GDP!G29/('Capital Est'!G29^(1/3)*Pop!G29^(2/3))) | H29: =IF(GDP!H29=0,"",GDP!H29/('Capital Est'!H29^(1/3)*Pop!H29^(2/3))) | I29: =IF(GDP!I29=0,"",GDP!I29/('Capital Est'!I29^(1/3)*Pop!I29^(2/3))) | ... L29: =IF(GDP!L29=0,"",GDP!L29/('Capital Est'!L29^(1/3)*Pop!L29^(2/3))) -> 0.069438362
A30: 28491 | B30: =IF(GDP!B30=0,"",GDP!B30/('Capital Est'!B30^(1/3)*Pop!B30^(2/3))) -> 0.092742092 | C30: =IF(GDP!C30=0,"",GDP!C30/('Capital Est'!C30^(1/3)*Pop!C30^(2/3))) -> 0.079423757 | D30: =IF(GDP!D30=0,"",GDP!D30/('Capital Est'!D30^(1/3)*Pop!D30^(2/3))) | E30: =IF(GDP!E30=0,"",GDP!E30/('Capital Est'!E30^(1/3)*Pop!E30^(2/3))) | F30: =IF(GDP!F30=0,"",GDP!F30/('Capital Est'!F30^(1/3)*Pop!F30^(2/3))) -> 0.049259275 | G30: =IF(GDP!G30=0,"",GDP!G30/('Capital Est'!G30^(1/3)*Pop!G30^(2/3))) | H30: =IF(GDP!H30=0,"",GDP!H30/('Capital Est'!H30^(1/3)*Pop!H30^(2/3))) | I30: =IF(GDP!I30=0,"",GDP!I30/('Capital Est'!I30^(1/3)*Pop!I30^(2/3))) | ... L30: =IF(GDP!L30=0,"",GDP!L30/('Capital Est'!L30^(1/3)*Pop!L30^(2/3))) -> 0.072133653
A31: 28856 | B31: =IF(GDP!B31=0,"",GDP!B31/('Capital Est'!B31^(1/3)*Pop!B31^(2/3))) -> 0.095259332 | C31: =IF(GDP!C31=0,"",GDP!C31/('Capital Est'!C31^(1/3)*Pop!C31^(2/3))) -> 0.080739696 | D31: =IF(GDP!D31=0,"",GDP!D31/('Capital Est'!D31^(1/3)*Pop!D31^(2/3))) | E31: =IF(GDP!E31=0,"",GDP!E31/('Capital Est'!E31^(1/3)*Pop!E31^(2/3))) | F31: =IF(GDP!F31=0,"",GDP!F31/('Capital Est'!F31^(1/3)*Pop!F31^(2/3))) -> 0.05028215 | G31: =IF(GDP!G31=0,"",GDP!G31/('Capital Est'!G31^(1/3)*Pop!G31^(2/3))) | H31: =IF(GDP!H31=0,"",GDP!H31/('Capital Est'!H31^(1/3)*Pop!H31^(2/3))) | I31: =IF(GDP!I31=0,"",GDP!I31/('Capital Est'!I31^(1/3)*Pop!I31^(2/3))) | ... L31: =IF(GDP!L31=0,"",GDP!L31/('Capital Est'!L31^(1/3)*Pop!L31^(2/3))) -> 0.073182977
A32: 29221 | B32: =IF(GDP!B32=0,"",GDP!B32/('Capital Est'!B32^(1/3)*Pop!B32^(2/3))) -> 0.095907491 | C32: =IF(GDP!C32=0,"",GDP!C32/('Capital Est'!C32^(1/3)*Pop!C32^(2/3))) -> 0.080665424 | D32: =IF(GDP!D32=0,"",GDP!D32/('Capital Est'!D32^(1/3)*Pop!D32^(2/3))) | E32: =IF(GDP!E32=0,"",GDP!E32/('Capital Est'!E32^(1/3)*Pop!E32^(2/3))) | F32: =IF(GDP!F32=0,"",GDP!F32/('Capital Est'!F32^(1/3)*Pop!F32^(2/3))) -> 0.050319654 | G32: =IF(GDP!G32=0,"",GDP!G32/('Capital Est'!G32^(1/3)*Pop!G32^(2/3))) | H32: =IF(GDP!H32=0,"",GDP!H32/('Capital Est'!H32^(1/3)*Pop!H32^(2/3))) | I32: =IF(GDP!I32=0,"",GDP!I32/('Capital Est'!I32^(1/3)*Pop!I32^(2/3))) | ... L32: =IF(GDP!L32=0,"",GDP!L32/('Capital Est'!L32^(1/3)*Pop!L32^(2/3))) -> 0.071964323
A33: 29587 | B33: =IF(GDP!B33=0,"",GDP!B33/('Capital Est'!B33^(1/3)*Pop!B33^(2/3))) -> 0.097541152 | C33: =IF(GDP!C33=0,"",GDP!C33/('Capital Est'!C33^(1/3)*Pop!C33^(2/3))) -> 0.081498578 | D33: =IF(GDP!D33=0,"",GDP!D33/('Capital Est'!D33^(1/3)*Pop!D33^(2/3))) | E33: =IF(GDP!E33=0,"",GDP!E33/('Capital Est'!E33^(1/3)*Pop!E33^(2/3))) | F33: =IF(GDP!F33=0,"",GDP!F33/('Capital Est'!F33^(1/3)*Pop!F33^(2/3))) -> 0.050162992 | G33: =IF(GDP!G33=0,"",GDP!G33/('Capital Est'!G33^(1/3)*Pop!G33^(2/3))) | H33: =IF(GDP!H33=0,"",GDP!H33/('Capital Est'!H33^(1/3)*Pop!H33^(2/3))) | I33: =IF(GDP!I33=0,"",GDP!I33/('Capital Est'!I33^(1/3)*Pop!I33^(2/3))) | ... L33: =IF(GDP!L33=0,"",GDP!L33/('Capital Est'!L33^(1/3)*Pop!L33^(2/3))) -> 0.07274489
A34: 29952 | B34: =IF(GDP!B34=0,"",GDP!B34/('Capital Est'!B34^(1/3)*Pop!B34^(2/3))) -> 0.094903597 | C34: =IF(GDP!C34=0,"",GDP!C34/('Capital Est'!C34^(1/3)*Pop!C34^(2/3))) -> 0.077437489 | D34: =IF(GDP!D34=0,"",GDP!D34/('Capital Est'!D34^(1/3)*Pop!D34^(2/3))) | E34: =IF(GDP!E34=0,"",GDP!E34/('Capital Est'!E34^(1/3)*Pop!E34^(2/3))) | F34: =IF(GDP!F34=0,"",GDP!F34/('Capital Est'!F34^(1/3)*Pop!F34^(2/3))) -> 0.050674375 | G34: =IF(GDP!G34=0,"",GDP!G34/('Capital Est'!G34^(1/3)*Pop!G34^(2/3))) | H34: =IF(GDP!H34=0,"",GDP!H34/('Capital Est'!H34^(1/3)*Pop!H34^(2/3))) | I34: =IF(GDP!I34=0,"",GDP!I34/('Capital Est'!I34^(1/3)*Pop!I34^(2/3))) | ... L34: =IF(GDP!L34=0,"",GDP!L34/('Capital Est'!L34^(1/3)*Pop!L34^(2/3))) -> 0.070538526
... A51: 36161 | B51: =IF(GDP!B51=0,"",GDP!B51/('Capital Est'!B51^(1/3)*Pop!B51^(2/3))) -> 0.12068119 | C51: =IF(GDP!C51=0,"",GDP!C51/('Capital Est'!C51^(1/3)*Pop!C51^(2/3))) -> 0.09296778 | D51: =IF(GDP!D51=0,"",GDP!D51/('Capital Est'!D51^(1/3)*Pop!D51^(2/3))) -> 0.061931084 | E51: =IF(GDP!E51=0,"",GDP!E51/('Capital Est'!E51^(1/3)*Pop!E51^(2/3))) -> 0.48951278 | F51: =IF(GDP!F51=0,"",GDP!F51/('Capital Est'!F51^(1/3)*Pop!F51^(2/3))) -> 0.061306604 | G51: =IF(GDP!G51=0,"",GDP!G51/('Capital Est'!G51^(1/3)*Pop!G51^(2/3))) -> 0.062438418 | H51: =IF(GDP!H51=0,"",GDP!H51/('Capital Est'!H51^(1/3)*Pop!H51^(2/3))) -> 0.060630395 | I51: =IF(GDP!I51=0,"",GDP!I51/('Capital Est'!I51^(1/3)*Pop!I51^(2/3))) -> 1.5170488 | ... L51: =IF(GDP!L51=0,"",GDP!L51/('Capital Est'!L51^(1/3)*Pop!L51^(2/3))) -> 0.09714584
A52: 36526 | B52: =IF(GDP!B52=0,"",GDP!B52/('Capital Est'!B52^(1/3)*Pop!B52^(2/3))) -> 0.12216469 | C52: =IF(GDP!C52=0,"",GDP!C52/('Capital Est'!C52^(1/3)*Pop!C52^(2/3))) -> 0.096037815 | D52: =IF(GDP!D52=0,"",GDP!D52/('Capital Est'!D52^(1/3)*Pop!D52^(2/3))) -> 0.063131209 | E52: =IF(GDP!E52=0,"",GDP!E52/('Capital Est'!E52^(1/3)*Pop!E52^(2/3))) -> 0.50588823 | F52: =IF(GDP!F52=0,"",GDP!F52/('Capital Est'!F52^(1/3)*Pop!F52^(2/3))) -> 0.062984731 | G52: =IF(GDP!G52=0,"",GDP!G52/('Capital Est'!G52^(1/3)*Pop!G52^(2/3))) -> 0.064498749 | H52: =IF(GDP!H52=0,"",GDP!H52/('Capital Est'!H52^(1/3)*Pop!H52^(2/3))) -> 0.062360296 | I52: =IF(GDP!I52=0,"",GDP!I52/('Capital Est'!I52^(1/3)*Pop!I52^(2/3))) -> 1.5377345 | ... L52: =IF(GDP!L52=0,"",GDP!L52/('Capital Est'!L52^(1/3)*Pop!L52^(2/3))) -> 0.098886595 | N52: =B52/B$62 -> 0.95334964 | O52: =C52/C$62 -> 1.0074104 | P52: =D52/D$62 -> 0.96193033 | Q52: =E52/E$62 -> 0.90311479 | R52: =F52/F$62 -> 0.99243272 | S52: =G52/G$62 -> 0.96580102 | T52: =H52/H$62 -> 1.0793924 | U52: =I52/I$62 -> 1.0231719 | ... X52: =L52/L$62 -> 0.99771597
A53: 36892 | B53: =IF(GDP!B53=0,"",GDP!B53/('Capital Est'!B53^(1/3)*Pop!B53^(2/3))) -> 0.12297623 | C53: =IF(GDP!C53=0,"",GDP!C53/('Capital Est'!C53^(1/3)*Pop!C53^(2/3))) -> 0.096000733 | D53: =IF(GDP!D53=0,"",GDP!D53/('Capital Est'!D53^(1/3)*Pop!D53^(2/3))) -> 0.063631997 | E53: =IF(GDP!E53=0,"",GDP!E53/('Capital Est'!E53^(1/3)*Pop!E53^(2/3))) -> 0.52035315 | F53: =IF(GDP!F53=0,"",GDP!F53/('Capital Est'!F53^(1/3)*Pop!F53^(2/3))) -> 0.063306877 | G53: =IF(GDP!G53=0,"",GDP!G53/('Capital Est'!G53^(1/3)*Pop!G53^(2/3))) -> 0.065507174 | H53: =IF(GDP!H53=0,"",GDP!H53/('Capital Est'!H53^(1/3)*Pop!H53^(2/3))) -> 0.062984085 | I53: =IF(GDP!I53=0,"",GDP!I53/('Capital Est'!I53^(1/3)*Pop!I53^(2/3))) -> 1.5238053 | ... L53: =IF(GDP!L53=0,"",GDP!L53/('Capital Est'!L53^(1/3)*Pop!L53^(2/3))) -> 0.097845684 | N53: =B53/B$62 -> 0.95968272 | O53: =C53/C$62 -> 1.0070214 | P53: =D53/D$62 -> 0.96956084 | Q53: =E53/E$62 -> 0.92893765 | R53: =F53/F$62 -> 0.99750869 | S53: =G53/G$62 -> 0.98090113 | T53: =H53/H$62 -> 1.0901896 | U53: =I53/I$62 -> 1.0139037 | ... X53: =L53/L$62 -> 0.9872137
A54: 37257 | B54: =IF(GDP!B54=0,"",GDP!B54/('Capital Est'!B54^(1/3)*Pop!B54^(2/3))) -> 0.12514612 | C54: =IF(GDP!C54=0,"",GDP!C54/('Capital Est'!C54^(1/3)*Pop!C54^(2/3))) -> 0.097082617 | D54: =IF(GDP!D54=0,"",GDP!D54/('Capital Est'!D54^(1/3)*Pop!D54^(2/3))) -> 0.06306306 | E54: =IF(GDP!E54=0,"",GDP!E54/('Capital Est'!E54^(1/3)*Pop!E54^(2/3))) -> 0.52927526 | F54: =IF(GDP!F54=0,"",GDP!F54/('Capital Est'!F54^(1/3)*Pop!F54^(2/3))) -> 0.063160344 | G54: =IF(GDP!G54=0,"",GDP!G54/('Capital Est'!G54^(1/3)*Pop!G54^(2/3))) -> 0.066007419 | H54: =IF(GDP!H54=0,"",GDP!H54/('Capital Est'!H54^(1/3)*Pop!H54^(2/3))) -> 0.062482844 | I54: =IF(GDP!I54=0,"",GDP!I54/('Capital Est'!I54^(1/3)*Pop!I54^(2/3))) -> 1.5078238 | ... L54: =IF(GDP!L54=0,"",GDP!L54/('Capital Est'!L54^(1/3)*Pop!L54^(2/3))) -> 0.0977129 | N54: =B54/B$62 -> 0.97661615 | O54: =C54/C$62 -> 1.0183701 | P54: =D54/D$62 -> 0.96089195 | Q54: =E54/E$62 -> 0.94486546 | R54: =F54/F$62 -> 0.99519981 | S54: =G54/G$62 -> 0.98839178 | T54: =H54/H$62 -> 1.0815136 | U54: =I54/I$62 -> 1.00327 | ... X54: =L54/L$62 -> 0.98587398
A55: 37622 | B55: =IF(GDP!B55=0,"",GDP!B55/('Capital Est'!B55^(1/3)*Pop!B55^(2/3))) -> 0.12610668 | C55: =IF(GDP!C55=0,"",GDP!C55/('Capital Est'!C55^(1/3)*Pop!C55^(2/3))) -> 0.097118841 | D55: =IF(GDP!D55=0,"",GDP!D55/('Capital Est'!D55^(1/3)*Pop!D55^(2/3))) -> 0.062394936 | E55: =IF(GDP!E55=0,"",GDP!E55/('Capital Est'!E55^(1/3)*Pop!E55^(2/3))) -> 0.53899297 | F55: =IF(GDP!F55=0,"",GDP!F55/('Capital Est'!F55^(1/3)*Pop!F55^(2/3))) -> 0.062960761 | G55: =IF(GDP!G55=0,"",GDP!G55/('Capital Est'!G55^(1/3)*Pop!G55^(2/3))) -> 0.067373682 | H55: =IF(GDP!H55=0,"",GDP!H55/('Capital Est'!H55^(1/3)*Pop!H55^(2/3))) -> 0.061789956 | I55: =IF(GDP!I55=0,"",GDP!I55/('Capital Est'!I55^(1/3)*Pop!I55^(2/3))) -> 1.5156125 | ... L55: =IF(GDP!L55=0,"",GDP!L55/('Capital Est'!L55^(1/3)*Pop!L55^(2/3))) -> 0.098662862 | N55: =B55/B$62 -> 0.98411215 | O55: =C55/C$62 -> 1.01875 | P55: =D55/D$62 -> 0.95071174 | Q55: =E55/E$62 -> 0.96221357 | R55: =F55/F$62 -> 0.99205503 | S55: =G55/G$62 -> 1.0088501 | T55: =H55/H$62 -> 1.0695204 | U55: =I55/I$62 -> 1.0084524 | ... X55: =L55/L$62 -> 0.99545861
A56: 37987 | B56: =IF(GDP!B56=0,"",GDP!B56/('Capital Est'!B56^(1/3)*Pop!B56^(2/3))) -> 0.12809493 | C56: =IF(GDP!C56=0,"",GDP!C56/('Capital Est'!C56^(1/3)*Pop!C56^(2/3))) -> 0.098247901 | D56: =IF(GDP!D56=0,"",GDP!D56/('Capital Est'!D56^(1/3)*Pop!D56^(2/3))) -> 0.062838291 | E56: =IF(GDP!E56=0,"",GDP!E56/('Capital Est'!E56^(1/3)*Pop!E56^(2/3))) -> 0.54971784 | F56: =IF(GDP!F56=0,"",GDP!F56/('Capital Est'!F56^(1/3)*Pop!F56^(2/3))) -> 0.063917491 | G56: =IF(GDP!G56=0,"",GDP!G56/('Capital Est'!G56^(1/3)*Pop!G56^(2/3))) -> 0.068235444 | H56: =IF(GDP!H56=0,"",GDP!H56/('Capital Est'!H56^(1/3)*Pop!H56^(2/3))) -> 0.061894063 | I56: =IF(GDP!I56=0,"",GDP!I56/('Capital Est'!I56^(1/3)*Pop!I56^(2/3))) -> 1.5358063 | ... L56: =IF(GDP!L56=0,"",GDP!L56/('Capital Est'!L56^(1/3)*Pop!L56^(2/3))) -> 0.10054278 | N56: =B56/B$62 -> 0.99962811 | O56: =C56/C$62 -> 1.0305936 | P56: =D56/D$62 -> 0.95746714 | Q56: =E56/E$62 -> 0.98135967 | R56: =F56/F$62 -> 1.00713 | S56: =G56/G$62 -> 1.0217541 | T56: =H56/H$62 -> 1.0713224 | U56: =I56/I$62 -> 1.0218889 | ... X56: =L56/L$62 -> 1.0144261
...
